Workbook

Sheet Summary
A1: Ubuntu 24.04 STIG → Omarchy triage (Omarchy owns kernel and repositories; not an Arch finding list)
A2: Source: DISA Canonical Ubuntu 24.04 LTS STIG V1R6 (manual XCCDF) + V1R5 SCAP 1.3 benchmark. Bucket and Status counts update live from the Triage tab.
A4: Bucket | B4: CAT I | C4: CAT II | D4: CAT III | E4: Total | F4: SCAP-auto
A5: As-is | B5: =COUNTIFS(Triage!$I$2:$I$195,$A5,Triage!$C$2:$C$195,"CAT I") | C5: =COUNTIFS(Triage!$I$2:$I$195,$A5,Triage!$C$2:$C$195,"CAT II") | D5: =COUNTIFS(Triage!$I$2:$I$195,$A5,Triage!$C$2:$C$195,"CAT III") | E5: =SUM(B5:D5) | F5: =COUNTIFS(Triage!$I$2:$I$195,$A5,Triage!$G$2:$G$195,"Yes")
A6: Translate | B6: =COUNTIFS(Triage!$I$2:$I$195,$A6,Triage!$C$2:$C$195,"CAT I") | C6: =COUNTIFS(Triage!$I$2:$I$195,$A6,Triage!$C$2:$C$195,"CAT II") | D6: =COUNTIFS(Triage!$I$2:$I$195,$A6,Triage!$C$2:$C$195,"CAT III") | E6: =SUM(B6:D6) | F6: =COUNTIFS(Triage!$I$2:$I$195,$A6,Triage!$G$2:$G$195,"Yes")
A7: Build | B7: =COUNTIFS(Triage!$I$2:$I$195,$A7,Triage!$C$2:$C$195,"CAT I") | C7: =COUNTIFS(Triage!$I$2:$I$195,$A7,Triage!$C$2:$C$195,"CAT II") | D7: =COUNTIFS(Triage!$I$2:$I$195,$A7,Triage!$C$2:$C$195,"CAT III") | E7: =SUM(B7:D7) | F7: =COUNTIFS(Triage!$I$2:$I$195,$A7,Triage!$G$2:$G$195,"Yes")
A8: Review: desktop | B8: =COUNTIFS(Triage!$I$2:$I$195,$A8,Triage!$C$2:$C$195,"CAT I") | C8: =COUNTIFS(Triage!$I$2:$I$195,$A8,Triage!$C$2:$C$195,"CAT II") | D8: =COUNTIFS(Triage!$I$2:$I$195,$A8,Triage!$C$2:$C$195,"CAT III") | E8: =SUM(B8:D8) | F8: =COUNTIFS(Triage!$I$2:$I$195,$A8,Triage!$G$2:$G$195,"Yes")
A9: Not applicable | B9: =COUNTIFS(Triage!$I$2:$I$195,$A9,Triage!$C$2:$C$195,"CAT I") | C9: =COUNTIFS(Triage!$I$2:$I$195,$A9,Triage!$C$2:$C$195,"CAT II") | D9: =COUNTIFS(Triage!$I$2:$I$195,$A9,Triage!$C$2:$C$195,"CAT III") | E9: =SUM(B9:D9) | F9: =COUNTIFS(Triage!$I$2:$I$195,$A9,Triage!$G$2:$G$195,"Yes")
A10: Policy answer | B10: =COUNTIFS(Triage!$I$2:$I$195,$A10,Triage!$C$2:$C$195,"CAT I") | C10: =COUNTIFS(Triage!$I$2:$I$195,$A10,Triage!$C$2:$C$195,"CAT II") | D10: =COUNTIFS(Triage!$I$2:$I$195,$A10,Triage!$C$2:$C$195,"CAT III") | E10: =SUM(B10:D10) | F10: =COUNTIFS(Triage!$I$2:$I$195,$A10,Triage!$G$2:$G$195,"Yes")
A11: Total | B11: =SUM(B5:B10) | C11: =SUM(C5:C10) | D11: =SUM(D5:D10) | E11: =SUM(E5:E10) | F11: =SUM(F5:F10)
A13: Status | B13: Count
A14: Not started | B14: =COUNTIF(Triage!$K$2:$K$195,$A14)
A15: In progress | B15: =COUNTIF(Triage!$K$2:$K$195,$A15)
A16: Done | B16: =COUNTIF(Triage!$K$2:$K$195,$A16)
A17: Open finding (POA&M) | B17: =COUNTIF(Triage!$K$2:$K$195,$A17)
A19: How to use
A20: Yellow cells on the Triage tab are yours to edit: Proposed bucket, Status, Arch check, Arch fix, Owner/notes.
A21: "Proposed bucket" was assigned by keyword heuristic from the Ubuntu check/fix text — review every row, especially the As-is ones.
A22: SCAP automated = the rule has OVAL content in the V1R5 benchmark; "OVAL check types" shows what the probe does (textfilecontent54 = grep a file, dpkginfo = package query → needs pacman rewrite, systemdunitproperty = systemctl state).
A23: Rules with dpkginfo checks are the ones whose OVAL must be rewritten for Arch even if the fix itself is trivial.
A24: Keep SRG-OS ID and CCI as the anchor when writing the Omarchy guide — those are what carry across every Linux STIG.

Sheet Triage
A1: Rule ID | B1: Vuln ID | C1: Severity | D1: SRG-OS ID | E1: CCIs | F1: Title | G1: SCAP automated? | H1: OVAL check types | I1: Proposed bucket | J1: Translation note (auto) | K1: Status | L1: Arch/Omarchy check | M1: Arch/Omarchy fix | N1: Owner / notes | O1: Ubuntu check text | P1: Ubuntu fix text | Q1: Vulnerability discussion
A2: UBTU-24-100010 | B2: V-270645 | C2: CAT III | D2: SRG-OS-000480-GPOS-00227 | E2: CCI-000366 | F2: Ubuntu 24.04 LTS must not have the "systemd-timesyncd" package installed. | G2: Yes | H2: dpkginfo | I2: Translate | J2: apt/dpkg → pacman -Q / pacman -Qkk / pacman.conf SigLevel | K2: Not started | O2: Verify the "systemd-timesyncd" package is not installed with the following command: $ dpkg -l | grep systemd-timesyncd If the "systemd-timesyncd" package is installed, this is a finding. | P2: The "systemd-timesyncd" package will be uninstalled as part of the "chrony" package install. Purge the remaining configuration files for "systemd-timesyncd" from Ubuntu 24.04 LTS: $ sudo apt-get purge systemd-timesyncd | Q2: Inaccurate time stamps make it more difficult to correlate events and can lead to an inaccurate analysis. Determining the correct time a particular event occurred on a system is critical when conducting forensic analysis and investigating system events. Sources outside the configured acceptable allowance (drift) may be inaccurate. Organizations must consider endpoints that may not have regular access to the authoritative time server (e.g., mobile, teleworking, and tactical endpoints).
A3: UBTU-24-100020 | B3: V-270646 | C3: CAT III | D3: SRG-OS-000480-GPOS-00227 | E3: CCI-000366 | F3: Ubuntu 24.04 LTS must not have the "ntp" package installed. | G3: Yes | H3: dpkginfo | I3: Translate | J3: apt/dpkg → pacman -Q / pacman -Qkk / pacman.conf SigLevel | K3: Not started | O3: Verify the "ntp" package is not installed with the following command: $ dpkg -l | grep ntp If the "ntp" package is installed, this is a finding. | P3: Uninstall the "ntp" package using the following command: $ sudo apt remove ntp If there are additional configuration files on the system that must be removed, the following command can be used instead: $ sudo apt-get purge ntp | Q3: Inaccurate time stamps make it more difficult to correlate events and can lead to an inaccurate analysis. Determining the correct time a particular event occurred on a system is critical when conducting forensic analysis and investigating system events. Sources outside the configured acceptable allowance (drift) may be inaccurate. Organizations must consider endpoints that may not have regular access to the authoritative time server (e.g., mobile, teleworking, and tactical endpoints).
A4: UBTU-24-100030 | B4: V-270647 | C4: CAT I | D4: SRG-OS-000074-GPOS-00042 | E4: CCI-000197 | F4: Ubuntu 24.04 LTS must not have the telnet package installed. | G4: Yes | H4: dpkginfo | I4: Build | J4: apt/dpkg → pacman -Q / pacman -Qkk / pacman.conf SigLevel | K4: Open finding (POA&M) | L4: pacman -Qo /usr/bin/telnetd; systemctl is-enabled telnet.socket ftpd.service telnetd.service | M4: Gov/mil preset: ship the base repository without a telnet server binary. Do not drop inetutils from the public image; hostname and ping come from that package. | N4: Phase 2. Parent V-203630. The Ubuntu check looks for a telnetd package. That package name is absent, and the heuristic Translate stops there. The base package list installs inetutils, which ships /usr/bin/telnetd and ftpd. Owning the base repository is how the server binary comes out. The public image keeps inetutils. | O4: Verify the telnet package is not installed on Ubuntu 24.04 LTS with the following command: $ dpkg -l | grep telnetd If the telnetd package is installed, this is a finding. | P4: Remove the telnet package from Ubuntu 24.04 LTS with the following command: $ sudo apt remove telnetd | Q4: Remote access services, such as those providing remote access to network devices and information systems, which lack automated control capabilities, increase risk and make remote user access management difficult at best. Remote access is access to DOD nonpublic information systems by an authorized user (or an information system) communicating through an external, nonorganization-controlled network. Remote access methods include, for example, dial-up, broadband, and wireless. Ubuntu 24.04 LTS functionality (e.g., RDP) must be capable of taking enforcement action if the audit reveals unauthorized activity. Automated control of remote access sessions allows organizations to ensure ongoing compliance with remote access policies by enforcing connection rules of remote access applications on a variety of information system components (e.g., servers, workstations, notebook computers, smartphones, and tablets).
A5: UBTU-24-100040 | B5: V-270648 | C5: CAT I | D5: SRG-OS-000095-GPOS-00049 | E5: CCI-000381 | F5: Ubuntu 24.04 LTS must not have the rsh-server package installed. | G5: Yes | H5: dpkginfo | I5: Translate | J5: apt/dpkg → pacman -Q / pacman -Qkk / pacman.conf SigLevel | K5: Done | L5: pacman -Q rsh-server; test ! -x /usr/bin/rshd | M5: None on the public image. The Omarchy base repository must not publish rsh-server. | N5: Phase 2. Parent SRG-OS-000095-GPOS-00049. rsh-server is not in install/omarchy-base.packages and is not installed on a current image. Translate to pacman is enough. Owning the base repository means the promise is 'we do not publish it,' not 'Arch does not.' | O5: Verify the rsh-server package is installed with the following command: $ dpkg -l | grep rsh-server If the rsh-server package is installed, this is a finding. | P5: Configure Ubuntu 24.04 LTS to disable nonessential capabilities by removing the rsh-server package from the system with the following command: $ sudo apt remove rsh-server | Q5: It is detrimental for operating systems to provide, or install by default, functionality exceeding requirements or mission objectives. These unnecessary capabilities or services are often overlooked and therefore, may remain unsecured. They increase the risk to the platform by providing additional attack vectors. Operating systems are capable of providing a wide variety of functions and services. Some of the functions and services, provided by default, may not be necessary to support essential organizational operations (e.g., key missions, functions). Examples of nonessential capabilities include, but are not limited to, games, software packages, tools, and demonstration software, not related to requirements or providing a wide array of functionality not required for every mission, but which cannot be disabled.
A6: UBTU-24-100050 | B6: V-279938 | C6: CAT I | D6: SRG-OS-000095-GPOS-00049 | E6: CCI-000381 | F6: Ubuntu 24.04 LTS must not have the nfs-kernel-server package installed. | G6: No (manual) | H6: — | I6: Translate | J6: apt/dpkg → pacman -Q / pacman -Qkk / pacman.conf SigLevel | K6: Done | L6: pacman -Q nfs-utils; systemctl list-unit-files 'nfs*' --no-legend | M6: None for the kernel server. Keep gvfs-nfs; it is the file-manager client, not nfs-kernel-server. | N6: Phase 2. Same parent as V-270648. The title forbids the NFS server. nfs-utils is not in the base list. The Ubuntu check also names nfs-common. Omarchy ships gvfs-nfs, which is not that server package. A preset that wants no NFS client code would remove gvfs-nfs; the public desktop does not. | O6: Verify Ubuntu 24.04 LTS does not have nfs packages installed. Check if packages are installed: $sudo dpkg -l | grep -E 'nfs-common | nfs-kernel-server' If the nfs-common or nfs-kernel-server packages are installed, this is a finding | P6: Configure Ubuntu 24.04 LTS to disable non-essential capabilities by removing the nfs-common and nfs-kernel-server packages from the system with the following commands: Remove packages if present: $ sudo apt purge --yes nfs-common nfs-kernel-server Remove any unneeded dependencies $ sudo apt autoremove --yes Verify NFS services are gone: $ sudo systemctl list-units --type=service | grep nfs | Q6: It is detrimental for operating systems to provide, or install by default, functionality exceeding requirements or mission objectives. These unnecessary capabilities or services are often overlooked and therefore may remain unsecured. They increase the risk to the platform by providing additional attack vectors. Operating systems are capable of providing a wide variety of functions and services. Some of the functions and services, provided by default, may not be necessary to support essential organizational operations (e.g., key missions, functions). Examples of non-essential capabilities include, but are not limited to, games, software packages, tools, and demonstration software, not related to requirements or providing a wide array of functionality not required for every mission, but which cannot be disabled.
A7: UBTU-24-100100 | B7: V-270649 | C7: CAT II | D7: SRG-OS-000445-GPOS-00199 | E7: CCI-002696 | F7: Ubuntu 24.04 LTS must use a file integrity tool to verify correct operation of all security functions. | G7: Yes | H7: dpkginfo | I7: Translate | J7: apt/dpkg → pacman -Q / pacman -Qkk / pacman.conf SigLevel | K7: Not started | O7: Verify that Advanced Intrusion Detection Environment (AIDE) is installed and verifies the correct operation of all security functions with the following command: $ dpkg -l | grep aide ii aide 0.18.6-2build2 amd64 Advanced Intrusion Detection Environment - dynamic binary ii aide-common 0.18.6-2build2 all Advanced Intrusion Detection Environment - Common files If AIDE is not installed, ask the system administrator how file integrity checks are performed on the system. If there is no application installed to perform integrity checks, this is a finding. | P7: Install the "AIDE" file integrity package: $ sudo apt install -y aide | Q7: Without verification, security functions may not operate correctly and the failure may go unnoticed. Security function is defined as the hardware, software, and/or firmware of the information system responsible for enforcing the system security policy and supporting the isolation of code and data on which the protection is based. Security functionality includes, but is not limited to, establishing system accounts, configuring access authorizations (i.e., permissions, privileges), setting events to be audited, and setting intrusion detection parameters. This requirement applies to Ubuntu 24.04 LTS performing security function verification/testing and/or systems and environments that require this functionality.
A8: UBTU-24-100110 | B8: V-270650 | C8: CAT II | D8: SRG-OS-000445-GPOS-00199 | E8: CCI-002696 | F8: Ubuntu 24.04 LTS must configure AIDE to perform file integrity checking on the file system if installed. | G8: No (manual) | H8: — | I8: Build | J8: AIDE is in extra/; write Arch-specific aide.conf and cron/timer | K8: Not started | O8: Note: If a file integrity tool other than Advanced Intrusion Detection Environment (AIDE) is employed, this requirement is not applicable. Verify AIDE is configured on the system by performing a manual check: $ sudo aide -c /etc/aide/aide.conf --check Example output: ... Start timestamp: 2024-10-30 14:22:38 -0400 (AIDE 0.18.6) AIDE found differences between database and filesystem!! ... If AIDE is being used for system file integrity checking and the command fails, this is a finding. | P8: Initialize the AIDE package (this may take a few minutes): $ sudo aideinit Running aide --init... The new database will need to be renamed to be read by AIDE: $ sudo cp -p /var/lib/aide/aide.db.new /var/lib/aide/aide.db Perform a manual check: $ sudo aide -c /etc/aide/aide.conf --check Example output: ... Start timestamp: 2024-10-30 14:22:38 -0400 (AIDE 0.18.6) AIDE found differences between database and filesystem!! ... Done. | Q8: Without verification, security functions may not operate correctly and the failure may go unnoticed. Security function is defined as the hardware, software, and/or firmware of the information system responsible for enforcing the system security policy and supporting the isolation of code and data on which the protection is based. Security functionality includes, but is not limited to, establishing system accounts, configuring access authorizations (i.e., permissions, privileges), setting events to be audited, and setting intrusion detection parameters. This requirement applies to Ubuntu 24.04 LTS performing security function verification/testing and/or systems and environments that require this functionality.
A9: UBTU-24-100120 | B9: V-270651 | C9: CAT II | D9: SRG-OS-000446-GPOS-00200 | E9: CCI-002699 | F9: Ubuntu 24.04 LTS must be configured so that the script which runs each 30 days or less to check file integrity is the default one. | G9: No (manual) | H9: — | I9: Translate | J9: apt/dpkg → pacman -Q / pacman -Qkk / pacman.conf SigLevel | K9: Not started | O9: Note: If AIDE is not installed, this finding is not applicable. Check the AIDE configuration file integrity installed on the system (the default configuration file is located at /etc/aide/aide.conf or in /etc/aide/aide.conf.d/) with the following command: $ sudo sha256sum /etc/aide/aide.conf f3bbea2552f2c5b475627850d8a5fba1659df6466986d5a18948d9821ecbe491 /etc/aide/aide.conf Download the original aide-common package in the /tmp directory: $ cd /tmp; apt download aide-common Generate the checksum from the aide.conf file in the downloaded .deb package: $ sudo dpkg-deb --fsys-tarfile /tmp/aide-common_0.18.6-2build2_all.deb | tar -xO ./usr/share/aide/config/aide/aide.conf | sha256sum f3bbea2552f2c5b475627850d8a5fba1659df6466986d5a18948d9821ecbe491 - If the checksums of the system file (/etc/aide/aide.conf) and the extracted file do not match, this is a finding. To verify the frequency of the file integrity checks, inspect the contents of the scheduled jobs as follows: Checking scheduled cron jobs: $ grep -r aide /etc/cron* /etc/crontab /etc/cron.daily/dailyaidecheck:SCRIPT="/usr/share/aide/bin/dailyaidecheck" Checking the systemd timer (this will show when the next scheduled run occurs and the last time the AIDE check was triggered): $ sudo systemctl list-timers | grep aide Thu 2024-10-31 02:01:58 EDT 10h Wed 2024-10-30 13:47:41 EDT - dailyaidecheck.timer dailyaidecheck.service The contents of these files can be inspected with the following commands: $ sudo systemctl cat dailyaidecheck.timer $ sudo systemctl cat dailyaidecheck.service If there is no AIDE script file in the cron directories or in the systemd timer, this is a finding. | P9: The cron file for AIDE is fairly complex as it creates the report. This file is installed with the "aide-common" package, and the default can be restored by copying it from the package: Download the original package to the /tmp dir: $ cd /tmp; apt download aide-common Extract the aide script to its original place: $ dpkg-deb --fsys-tarfile /tmp/aide-common_*.deb | sudo tar -x --wildcards ./usr/share/aide/config/cron.daily/dailyaidecheck* -C / Copy it to the cron.daily directory: $ sudo cp -f /usr/share/aide/config/cron.daily/aide /etc/cron.daily/dailyaidecheck* | Q9: Without verification, security functions may not operate correctly and the failure may go unnoticed. Security function is defined as the hardware, software, and/or firmware of the information system responsible for enforcing the system security policy and supporting the isolation of code and data on which the protection is based. Security functionality includes, but is not limited to, establishing system accounts, configuring access authorizations (i.e., permissions, privileges), setting events to be audited, and setting intrusion detection parameters. Notifications provided by information systems include, for example, electronic alerts to system administrators, messages to local computer consoles, and/or hardware indications, such as lights. This requirement applies to Ubuntu 24.04 LTS performing security function verification/testing and/or systems and environments that require this functionality.
A10: UBTU-24-100130 | B10: V-270652 | C10: CAT II | D10: SRG-OS-000447-GPOS-00201 | E10: CCI-002702, CCI-001744 | F10: Ubuntu 24.04 LTS must notify designated personnel if baseline configurations are changed in an unauthorized manner. The file integrity tool must notify the system administrator (SA) when changes to the baseline configuration or anomalies in the operation of any security functions are discovered. | G10: Yes | H10: textfilecontent54 | I10: As-is | J10: Verify path/package name on Arch | K10: Not started | O10: Verify that Advanced Intrusion Detection Environment (AIDE) notifies the SA when anomalies in the operation of any security functions are discovered with the following command: $ grep SILENTREPORTS /etc/default/aide SILENTREPORTS=no If "SILENTREPORTS" is set to "yes", is commented out, or is missing, this is a finding. | P10: Configure Ubuntu 24.04 LTS to notify designated personnel if baseline configurations are changed in an unauthorized manner. Modify the "SILENTREPORTS" parameter in the "/etc/default/aide" file with a value of "no" if it does not already exist as follows: SILENTREPORTS=no | Q10: Unauthorized changes to the baseline configuration could make the system vulnerable to various attacks or allow unauthorized access to Ubuntu 24.04 LTS. Changes to Ubuntu 24.04 LTS configurations can have unintended side effects, some of which may be relevant to security. Detecting such changes and providing an automated response can help avoid unintended, negative consequences that could ultimately affect the security state of Ubuntu 24.04 LTS. Ubuntu 24.04 LTS' IMO/information system security officer (ISSO) and SAs must be notified via email and/or monitoring system trap when there is an unauthorized modification of a configuration item. Satisfies: SRG-OS-000447-GPOS-00201, SRG-OS-000363-GPOS-00150
A11: UBTU-24-100200 | B11: V-270653 | C11: CAT II | D11: SRG-OS-000269-GPOS-00103 | E11: CCI-001665 | F11: Ubuntu 24.04 LTS must be configured to preserve log records from failure events. | G11: Yes | H11: dpkginfo, systemdunitproperty | I11: Translate | J11: apt/dpkg → pacman -Q / pacman -Qkk / pacman.conf SigLevel | K11: Not started | O11: Verify the log service is installed properly with the following command: $ dpkg -l | grep rsyslog ii rsyslog 8.2312.0-3ubuntu9 amd64 reliable system and kernel logging daemon If the "rsyslog" package is not installed, this is a finding. Check that the log service is enabled with the following command: $ systemctl is-enabled rsyslog enabled If the command above returns "disabled", this is a finding. Check that the log service is properly running and active on the system with the following command: $ systemctl is-active rsyslog active If the command above returns "inactive", this is a finding. | P11: Configure the log service to collect failure events. Install the log service (if the log service is not already installed) with the following command: $ sudo apt install -y rsyslog Enable the log service with the following command: $ sudo systemctl enable --now rsyslog | Q11: Failure to a known state can address safety or security in accordance with the mission/business needs of the organization. Failure to a known secure state helps prevent a loss of confidentiality, integrity, or availability in the event of a failure of the information system or a component of the system. Preserving operating system state information helps to facilitate operating system restart and return to the operational mode of the organization with least disruption to mission/business processes.
A12: UBTU-24-100300 | B12: V-270654 | C12: CAT II | D12: SRG-OS-000297-GPOS-00115 | E12: CCI-002314 | F12: Ubuntu 24.04 LTS must have an application firewall installed in order to control remote access methods. | G12: Yes | H12: dpkginfo | I12: Translate | J12: apt/dpkg → pacman -Q / pacman -Qkk / pacman.conf SigLevel | K12: Not started | O12: Verify that the Uncomplicated Firewall (ufw) is installed with the following command: $ dpkg -l | grep ufw ii ufw 0.36.2-6 all program for managing a Netfilter firewall If the "ufw" package is not installed, ask the system administrator if another application firewall is installed. If no application firewall is installed, this is a finding. | P12: Install the ufw by using the following command: $ sudo apt install -y ufw | Q12: Remote access services, such as those providing remote access to network devices and information systems, which lack automated control capabilities, increase risk, and make remote user access management difficult at best. Remote access is access to DOD nonpublic information systems by an authorized user (or an information system) communicating through an external, nonorganization-controlled network. Remote access methods include, for example, dial-up, broadband, and wireless. Ubuntu 24.04 LTS functionality (e.g., RDP) must be capable of taking enforcement action if the audit reveals unauthorized activity. Automated control of remote access sessions allows organizations to ensure ongoing compliance with remote access policies by enforcing connection rules of remote access applications on a variety of information system components (e.g., servers, workstations, notebook computers, smartphones, and tablets).
A13: UBTU-24-100310 | B13: V-270655 | C13: CAT II | D13: SRG-OS-000297-GPOS-00115 | E13: CCI-002314 | F13: Ubuntu 24.04 LTS must enable and run the Uncomplicated Firewall (ufw). | G13: Yes | H13: systemdunitproperty | I13: Translate | J13: ufw → nftables | K13: Not started | O13: Verify the ufw is enabled on the system with the following command: $ sudo ufw status Status: active If the above command returns the status as "inactive" or any type of error, this is a finding. If the ufw is not installed, ask the system administrator if another application firewall is installed. If a different firewall is active on the system, this is not a finding. | P13: Enable the ufw by using the following command: $ sudo ufw enable Note: Enabling the firewall will potentially disrupt ssh sessions. | Q13: Remote access services, such as those providing remote access to network devices and information systems, which lack automated control capabilities, increase risk, and make remote user access management difficult at best. Remote access is access to DOD nonpublic information systems by an authorized user (or an information system) communicating through an external, nonorganization-controlled network. Remote access methods include, for example, dial-up, broadband, and wireless. Ubuntu 24.04 LTS functionality (e.g., RDP) must be capable of taking enforcement action if the audit reveals unauthorized activity. Automated control of remote access sessions allows organizations to ensure ongoing compliance with remote access policies by enforcing connection rules of remote access applications on a variety of information system components (e.g., servers, workstations, notebook computers, smartphones, and tablets). Satisfies: SRG-OS-000297-GPOS-00115, SRG-OS-000480-GPOS-00232
A14: UBTU-24-100400 | B14: V-270656 | C14: CAT II | D14: SRG-OS-000365-GPOS-00152 | E14: CCI-003938, CCI-001914, CCI-000169, CCI-000172, CCI-000135, CCI-000130, CCI-000131, CCI-000132, CCI-000133, CCI-000134, CCI-000154, CCI-000158, CCI-001876, CCI-001875, CCI-001877, CCI-001878, CCI-001879, CCI-001880, CCI-001881, CCI-001882 | F14: Ubuntu 24.04 LTS must have the "auditd" package installed. | G14: Yes | H14: dpkginfo | I14: Translate | J14: apt/dpkg → pacman -Q / pacman -Qkk / pacman.conf SigLevel | K14: Not started | O14: Verify the audit service is configured to produce audit records with the following command: $ dpkg -l | grep auditd ii auditd 1:3.0.7-1build1 amd64 User space tools for security auditing If the "auditd" package is not installed, this is a finding. | P14: Configure the audit service to produce audit records containing the information needed to establish when (date and time) an event occurred. Install the audit service (if the audit service is not already installed) with the following command: $ sudo apt install -y auditd | Q14: Without establishing the when, where, type, source, and outcome of events that occurred, it would be difficult to establish, correlate, and investigate the events leading up to an outage or attack. Without the capability to generate audit records, it would be difficult to establish, correlate, and investigate the events relating to an incident or identify those responsible for one. Audit record content that may be necessary to satisfy this requirement includes, for example, time stamps, source and destination addresses, user/process identifiers, event descriptions, success/fail indications, filenames involved, and access control or flow control rules invoked. Reconstruction of harmful events or forensic analysis is not possible if audit records do not contain enough information. Successful incident response and auditing relies on timely, accurate system information and analysis to allow the organization to identify and respond to potential incidents in a proficient manner. If Ubuntu 24.04 LTS does not provide the ability to centrally review Ubuntu 24.04 LTS logs, forensic analysis is negatively impacted. Associating event types with detected events in Ubuntu 24.04 LTS audit logs provides a means of investigating an attack; recognizing resource utilization or capacity thresholds; or identifying an improperly configured operating system. Satisfies: SRG-OS-000365-GPOS-00152, SRG-OS-000337-GPOS-00129, SRG-OS-000062-GPOS-00031, SRG-OS-000475-GPOS-00220, SRG-OS-000042-GPOS-00020, SRG-OS-000042-GPOS-00021, SRG-OS-000037-GPOS-00015, SRG-OS-000038-GPOS-00016, SRG-OS-000039-GPOS-00017, SRG-OS-000040-GPOS-00018, SRG-OS-000041-GPOS-00019, SRG-OS-000051-GPOS-00024, SRG-OS-000054-GPOS-00025, SRG-OS-000122-GPOS-00063, SRG-OS-000348-GPOS-00136, SRG-OS-000349-GPOS-00137, SRG-OS-000350-GPOS-00138, SRG-OS-000351-GPOS-00139, SRG-OS-000352-GPOS-00140, SRG-OS-000353-GPOS-00141, SRG-OS-000354-GPOS-00142
A15: UBTU-24-100410 | B15: V-270657 | C15: CAT II | D15: SRG-OS-000365-GPOS-00152 | E15: CCI-003938, CCI-001914, CCI-000169, CCI-000172, CCI-000135, CCI-000130, CCI-000131, CCI-000132, CCI-000133, CCI-000134, CCI-000154, CCI-000158, CCI-001876, CCI-001875, CCI-001877, CCI-001878, CCI-001879, CCI-001880, CCI-001881, CCI-001882 | F15: Ubuntu 24.04 LTS must produce audit records and reports containing information to establish when, where, what type, the source, and the outcome for all DOD-defined auditable events and actions in near real time. | G15: Yes | H15: systemdunitproperty | I15: As-is | J15: Distro-agnostic; verify file paths on Arch | K15: Not started | O15: Verify the audit service is enabled with the following command: $ systemctl is-enabled auditd.service enabled If the command above returns "disabled", this is a finding. Verify the audit service is properly running and active on the system with the following command: $ systemctl is-active auditd.service active If the command above returns "inactive", this is a finding. | P15: Configure the audit service to produce audit records containing the information needed to establish when (date and time) an event occurred. Enable the audit service with the following command: $ sudo systemctl enable auditd.service To reload the rules file, issue the following command: $ sudo augenrules --load | Q15: Without establishing the when, where, type, source, and outcome of events that occurred, it would be difficult to establish, correlate, and investigate the events leading up to an outage or attack. Without the capability to generate audit records, it would be difficult to establish, correlate, and investigate the events relating to an incident or identify those responsible for one. Audit record content that may be necessary to satisfy this requirement includes, for example, time stamps, source and destination addresses, user/process identifiers, event descriptions, success/fail indications, filenames involved, and access control or flow control rules invoked. Reconstruction of harmful events or forensic analysis is not possible if audit records do not contain enough information. Successful incident response and auditing relies on timely, accurate system information and analysis to allow the organization to identify and respond to potential incidents in a proficient manner. If Ubuntu 24.04 LTS does not provide the ability to centrally review Ubuntu 24.04 LTS logs, forensic analysis is negatively impacted. Associating event types with detected events in Ubuntu 24.04 LTS audit logs provides a means of investigating an attack; recognizing resource utilization or capacity thresholds; or identifying an improperly configured operating system. Satisfies: SRG-OS-000365-GPOS-00152, SRG-OS-000337-GPOS-00129, SRG-OS-000062-GPOS-00031, SRG-OS-000475-GPOS-00220, SRG-OS-000042-GPOS-00020, SRG-OS-000042-GPOS-00021, SRG-OS-000037-GPOS-00015, SRG-OS-000038-GPOS-00016, SRG-OS-000039-GPOS-00017, SRG-OS-000040-GPOS-00018, SRG-OS-000041-GPOS-00019, SRG-OS-000051-GPOS-00024, SRG-OS-000054-GPOS-00025, SRG-OS-000122-GPOS-00063, SRG-OS-000348-GPOS-00136, SRG-OS-000349-GPOS-00137, SRG-OS-000350-GPOS-00138, SRG-OS-000351-GPOS-00139, SRG-OS-000352-GPOS-00140, SRG-OS-000353-GPOS-00141, SRG-OS-000354-GPOS-00142
A16: UBTU-24-100450 | B16: V-270658 | C16: CAT III | D16: SRG-OS-000342-GPOS-00133 | E16: CCI-001851 | F16: Ubuntu 24.04 LTS audit event multiplexor must be configured to offload audit logs onto a different system or storage media from the system being audited. | G16: No (manual) | H16: — | I16: Translate | J16: apt/dpkg → pacman -Q / pacman -Qkk / pacman.conf SigLevel | K16: Not started | O16: Verify the audit event multiplexor is configured to offload audit records to a different system or storage media from the system being audited. Check that audisp-remote plugin is installed: $ dpkg -l | grep audispd-plugins ii audispd-plugins 1:3.1.2-2.1build1.1 amd64 Plugins for the audit event dispatcher If the packet is "not installed", this is a finding. Check that the records are being offloaded to a remote server with the following command: $ sudo grep -i active /etc/audit/plugins.d/au-remote.conf active = yes If "active" is not set to "yes", or the line is commented out, or is missing, this is a finding. Check that audisp-remote plugin is configured to send audit logs to a different system: $ sudo grep -i ^remote_server /etc/audit/audisp-remote.conf remote_server = 192.168.122.126 If the "remote_server" parameter is not set, is set with a local address, or is set with an invalid address, this is a finding. | P16: Configure the audit event multiplexor to offload audit records to a different system or storage media from the system being audited. Install the audisp-remote plugin: $ sudo apt install -y audispd-plugins Set the audisp-remote plugin as active by editing the "/etc/audit/plugins.d/au-remote.conf" file: $ sudo sed -i -E 's/active\s*=\s*no/active = yes/' /etc/audit/plugins.d/au-remote.conf Set the address of the remote machine by editing the "/etc/audit/audisp-remote.conf" file: $ sudo sed -i -E 's/(remote_server\s*=).*/\1 <remote addr>/' /etc/audit/audisp-remote.conf where <remote addr> must be substituted by the address of the remote server receiving the audit log. Make the audit service reload its configuration files: $ sudo systemctl restart auditd.service | Q16: Information stored in one location is vulnerable to accidental or incidental deletion or alteration. Offloading is a common process in information systems with limited audit storage capacity. Satisfies: SRG-OS-000342-GPOS-00133, SRG-OS-000479-GPOS-00224
A17: UBTU-24-100500 | B17: V-270659 | C17: CAT II | D17: SRG-OS-000312-GPOS-00124 | E17: CCI-002165, CCI-001764, CCI-001774 | F17: Ubuntu 24.04 LTS must have AppArmor installed. | G17: Yes | H17: dpkginfo | I17: Build | J17: Arch ships apparmor but no profiles; port from Ubuntu apparmor-profiles | K17: Not started | O17: Verify Ubuntu 24.04 LTS has AppArmor installed with the following command: $ dpkg -l | grep apparmor ii apparmor 4.0.1really4.0.1-0ubuntu0.24.04.3 amd64 user-space parser utility for AppArmor ii libapparmor1:amd64 4.0.1really4.0.1-0ubuntu0.24.04.3 amd64 changehat AppArmor library If the AppArmor package is not installed, this is a finding. | P17: Install "AppArmor" with the following command: $ sudo apt install apparmor Note: AppArmor must have properly configured profiles for applications and home directories. All configurations will be based on the actual system setup and organization and normally are on a per role basis. Refer to the AppArmor documentation for more information on configuring profiles. | Q17: Control of program execution is a mechanism used to prevent execution of unauthorized programs. Some operating systems may provide a capability that runs counter to the mission or provides users with functionality that exceeds mission requirements. This includes functions and services installed at Ubuntu 24.04 LTS-level. Some of the programs, installed by default, may be harmful or may not be necessary to support essential organizational operations (e.g., key missions, functions). Removal of executable programs is not always possible; therefore, establishing a method of preventing program execution is critical to maintaining a secure system baseline. Methods for complying with this requirement include restricting execution of programs in certain environments, while preventing execution in other environments; or limiting execution of certain program functionality based on organization-defined criteria (e.g., privileges, subnets, sandboxed environments, or roles). Satisfies: SRG-OS-000312-GPOS-00124, SRG-OS-000368-GPOS-00154, SRG-OS-000370-GPOS-00155
A18: UBTU-24-100510 | B18: V-270660 | C18: CAT II | D18: SRG-OS-000368-GPOS-00154 | E18: CCI-001764, CCI-002235, CCI-001774 | F18: Ubuntu 24.04 LTS must be configured to use AppArmor. | G18: Yes | H18: systemdunitproperty | I18: Build | J18: Arch ships apparmor but no profiles; port from Ubuntu apparmor-profiles | K18: Not started | O18: Verify Ubuntu 24.04 LTS AppArmor active with the following commands: $ systemctl is-active apparmor.service active If "active" is not returned, this is a finding. $ systemctl is-enabled apparmor.service enabled If "enabled" is not returned, this is a finding. | P18: Enable "apparmor" with the following command: $ sudo systemctl enable apparmor.service Start "apparmor" with the following command: $ sudo systemctl start apparmor.service Note: AppArmor must have properly configured profiles for applications and home directories. All configurations will be based on the actual system setup and organization and normally are on a per role basis. Refer to the AppArmor documentation for more information on configuring profiles. | Q18: Control of program execution is a mechanism used to prevent execution of unauthorized programs. Some operating systems may provide a capability that runs counter to the mission or provides users with functionality that exceeds mission requirements. This includes functions and services installed at Ubuntu 24.04 LTS-level. Some of the programs, installed by default, may be harmful or may not be necessary to support essential organizational operations (e.g., key missions, functions). Removal of executable programs is not always possible; therefore, establishing a method of preventing program execution is critical to maintaining a secure system baseline. Methods for complying with this requirement include restricting execution of programs in certain environments, while preventing execution in other environments; or limiting execution of certain program functionality based on organization-defined criteria (e.g., privileges, subnets, sandboxed environments, or roles). Satisfies: SRG-OS-000368-GPOS-00154, SRG-OS-000324-GPOS-00125, SRG-OS-000370-GPOS-00155
... A22: UBTU-24-100700 | B22: V-270664 | C22: CAT III | D22: SRG-OS-000480-GPOS-00227 | E22: CCI-000366 | F22: Ubuntu 24.04 LTS must have the "chrony" package installed. | G22: Yes | H22: dpkginfo | I22: Translate | J22: apt/dpkg → pacman -Q / pacman -Qkk / pacman.conf SigLevel | K22: Not started | O22: Verify the "chrony" package is installed using the following command: $ dpkg -l | grep chrony ii chrony 4.5-1ubuntu4.1 amd64 Versatile implementation of the Network Time Protocol If the "chrony" package is not installed, this is a finding. | P22: Install the "chrony" network time protocol package using the following command: $ sudo apt install -y chrony | Q22: Inaccurate time stamps make it more difficult to correlate events and can lead to an inaccurate analysis. Determining the correct time a particular event occurred on a system is critical when conducting forensic analysis and investigating system events. Sources outside the configured acceptable allowance (drift) may be inaccurate. Organizations must consider endpoints that may not have regular access to the authoritative time server (e.g., mobile, teleworking, and tactical endpoints).
A23: UBTU-24-100800 | B23: V-270665 | C23: CAT I | D23: SRG-OS-000423-GPOS-00187 | E23: CCI-002418, CCI-002420, CCI-002422 | F23: Ubuntu 24.04 LTS must have SSH installed. | G23: Yes | H23: dpkginfo | I23: Policy answer | J23: apt/dpkg → pacman -Q / pacman -Qkk / pacman.conf SigLevel | K23: Open finding (POA&M) | L23: pacman -Q openssh; systemctl is-enabled sshd.service | M23: Gov/mil preset: put openssh in the base repository and enable sshd only with a key already authorized. Public image: leave it out until omarchy-setup-security-sshd. | N23: Phase 2. Parent V-203748. openssh is not in install/omarchy-base.packages. omarchy-setup-security-sshd installs it and enables sshd. Ubuntu treats 'server package absent' as a finding. Omarchy treats that absence as the default. Those are opposite policies. The fork does not force the Ubuntu answer onto the public image. | O23: Verify the SSH package is installed with the following command: $ dpkg -l | grep openssh ii openssh-client 1:9.6p1-3ubuntu13.5 amd64 secure shell (SSH) client, for secure access to remote machines ii openssh-server 1:9.6p1-3ubuntu13.5 amd64 secure shell (SSH) server, for secure access from remote machines ii openssh-sftp-server 1:9.6p1-3ubuntu13.5 amd64 secure shell (SSH) sftp server module, for SFTP access from remote machines If the "openssh" server package is not installed, this is a finding. | P23: Install the "ssh" meta-package on the system with the following command: $ sudo apt install -y ssh | Q23: Without protection of the transmitted information, confidentiality and integrity may be compromised because unprotected communications can be intercepted and either read or altered. This requirement applies to both internal and external networks and all types of information system components from which information can be transmitted (e.g., servers, mobile devices, notebook computers, printers, copiers, scanners, and facsimile machines). Communication paths outside the physical protection of a controlled boundary are exposed to the possibility of interception and modification. Protecting the confidentiality and integrity of organizational information can be accomplished by physical means (e.g., employing physical distribution systems) or by logical means (e.g., employing cryptographic techniques). If physical means of protection are employed, then logical means (cryptography) do not have to be employed, and vice versa. Satisfies: SRG-OS-000423-GPOS-00187, SRG-OS-000425-GPOS-00189, SRG-OS-000426-GPOS-00190
A24: UBTU-24-100810 | B24: V-270666 | C24: CAT I | D24: SRG-OS-000423-GPOS-00187 | E24: CCI-002418, CCI-002420, CCI-002422 | F24: Ubuntu 24.04 LTS must use SSH to protect the confidentiality and integrity of transmitted information. | G24: Yes | H24: systemdunitproperty | I24: Policy answer | J24: Distro-agnostic; verify file paths on Arch | K24: Open finding (POA&M) | L24: systemctl is-enabled sshd.service; systemctl is-active sshd.service | M24: Do not enable sshd on the public image. A preset that enables it uses omarchy-setup-security-sshd, which refuses to turn off password logins until a key is authorized. | N24: Phase 2. Same parent as V-270665. install/config/enable-services.sh does not enable sshd. Heuristic As-is is rejected. Package mirrors are HTTPS, not SSH. Owning the repositories does not mean every flow must pass through sshd. | O24: Verify the "sshd.service" is enabled and active with the following commands: $ sudo systemctl is-enabled ssh enabled $ sudo systemctl is-active ssh active If "ssh.service" is not active or loaded, this is a finding. | P24: Enable the "ssh" service to start automatically on reboot with the following command: $ sudo systemctl enable ssh.service ensure the "ssh" service is running $ sudo systemctl start ssh.service | Q24: Without protection of the transmitted information, confidentiality and integrity may be compromised because unprotected communications can be intercepted and either read or altered. This requirement applies to both internal and external networks and all types of information system components from which information can be transmitted (e.g., servers, mobile devices, notebook computers, printers, copiers, scanners, and facsimile machines). Communication paths outside the physical protection of a controlled boundary are exposed to the possibility of interception and modification. Protecting the confidentiality and integrity of organizational information can be accomplished by physical means (e.g., employing physical distribution systems) or by logical means (e.g., employing cryptographic techniques). If physical means of protection are employed, then logical means (cryptography) do not have to be employed, and vice versa. Satisfies: SRG-OS-000423-GPOS-00187, SRG-OS-000425-GPOS-00189, SRG-OS-000426-GPOS-00190
A25: UBTU-24-100820 | B25: V-270667 | C25: CAT II | D25: SRG-OS-000033-GPOS-00014 | E25: CCI-000068, CCI-003123, CCI-002421 | F25: Ubuntu 24.04 LTS must configure the SSH daemon to use FIPS 140-3 approved ciphers to prevent the unauthorized disclosure of information and/or detect changes to information during transmission. | G25: Yes | H25: textfilecontent54 | I25: Build | J25: No CMVP-validated module for Arch — decide FIPS lane first | K25: In progress | N25: Phase 1. Parent SRG-OS-000033-GPOS-00014 (GPOS V-203603) is partial. This rule requires FIPS 140-3 SSH ciphers. Omarchy does not pin them. An Omarchy-owned kernel and base repository would make a later FIPS preset possible. That preset is not the public image. Open finding when the check is written. Heuristic Build is the right kind of work, not a default change. | O25: Verify that the SSH daemon is configured to implement only FIPS-approved algorithms with the following command: $ sudo grep -r 'Ciphers' /etc/ssh/sshd_config* Ciphers aes256-gcm@openssh.com,aes128-gcm@openssh.com,aes256-ctr,aes128-ctr If any ciphers other than "Ciphers aes256-gcm@openssh.com,aes128-gcm@openssh.com,aes256-ctr,aes128-ctr" are listed, the "Ciphers" keyword is missing, or the returned line is commented out, or if multiple conflicting ciphers are returned, this is a finding. | P25: Configure Ubuntu 24.04 LTS to allow the SSH daemon to only implement FIPS-approved algorithms. Add the following line (or modify the line to have the required value) to the "/etc/ssh/sshd_config" file (this file may be named differently or be in a different location if using a version of SSH that is provided by a third-party vendor): Ciphers aes256-gcm@openssh.com,aes128-gcm@openssh.com,aes256-ctr,aes128-ctr Restart the "sshd" service for changes to take effect: $ sudo systemctl restart sshd | Q25: Without cryptographic integrity protections, information can be altered by unauthorized users without detection. Remote access (e.g., RDP) is access to DOD nonpublic information systems by an authorized user (or an information system) communicating through an external, nonorganization-controlled network. Remote access methods include, for example, dial-up, broadband, and wireless. Nonlocal maintenance and diagnostic activities are those activities conducted by individuals communicating through a network, either an external network (e.g., the internet) or an internal network. Local maintenance and diagnostic activities are those activities carried out by individuals physically present at the information system or information system component and not communicating across a network connection. Encrypting information for transmission protects information from unauthorized disclosure and modification. Cryptographic mechanisms implemented to protect information integrity include, for example, cryptographic hash functions that have common application in digital signatures, checksums, and message authentication codes. Satisfies: SRG-OS-000033-GPOS-00014, SRG-OS-000394-GPOS-00174, SRG-OS-000424-GPOS-00188
A26: UBTU-24-100830 | B26: V-270668 | C26: CAT II | D26: SRG-OS-000250-GPOS-00093 | E26: CCI-001453, CCI-002890, CCI-002421 | F26: Ubuntu 24.04 LTS must configure the SSH daemon to use Message Authentication Codes (MACs) employing FIPS 140-3 approved cryptographic hashes to prevent the unauthorized disclosure of information and/or detect changes to information during transmission. | G26: Yes | H26: textfilecontent54 | I26: Build | J26: No CMVP-validated module for Arch — decide FIPS lane first | K26: In progress | N26: Phase 1. Parent SRG-OS-000250-GPOS-00093 (GPOS V-203669) is partial. FIPS MAC policy for sshd. Not pinned today. Forking the base repository does not by itself select those MACs. Open finding for the public image. | O26: Verify the SSH daemon is configured to only use MACs that employ FIPS 140-3 approved ciphers with the following command: $ grep -irs macs /etc/ssh/sshd_config* MACs hmac-sha2-512-etm@openssh.com,hmac-sha2-256-etm@openssh.com,hmac-sha2-512,hmac-sha2-256 If any algorithms other than "hmac-sha2-512-etm@openssh.com,hmac-sha2-256-etm@openssh.com,hmac-sha2-512,hmac-sha2-256" are listed, the returned line is commented out, or if conflicting results are returned, this is a finding. | P26: Configure Ubuntu 24.04 LTS to allow the SSH daemon to only use MACs that employ FIPS 140-3 approved ciphers. Add the following line (or modify the line to have the required value) to the "/etc/ssh/sshd_config" file (this file may be named differently or be in a different location if using a version of SSH that is provided by a third-party vendor): MACs hmac-sha2-512-etm@openssh.com,hmac-sha2-256-etm@openssh.com,hmac-sha2-512,hmac-sha2-256 Restart the "sshd" service for changes to take effect: $ sudo systemctl restart sshd | Q26: Without cryptographic integrity protections, information can be altered by unauthorized users without detection. Remote access (e.g., RDP) is access to DOD nonpublic information systems by an authorized user (or an information system) communicating through an external, nonorganization-controlled network. Remote access methods include, for example, dial-up, broadband, and wireless. Nonlocal maintenance and diagnostic activities are those activities conducted by individuals communicating through a network, either an external network (e.g., the internet) or an internal network. Local maintenance and diagnostic activities are those activities carried out by individuals physically present at the information system or information system component and not communicating across a network connection. Encrypting information for transmission protects information from unauthorized disclosure and modification. Cryptographic mechanisms implemented to protect information integrity include, for example, cryptographic hash functions that have common application in digital signatures, checksums, and message authentication codes. Satisfies: SRG-OS-000250-GPOS-00093, SRG-OS-000393-GPOS-00173, SRG-OS-000424-GPOS-00188
A27: UBTU-24-100840 | B27: V-270669 | C27: CAT II | D27: SRG-OS-000033-GPOS-00014 | E27: CCI-000068 | F27: Ubuntu 24.04 LTS SSH server must be configured to use only FIPS 140-3 validated key exchange algorithms. | G27: Yes | H27: textfilecontent54 | I27: Build | J27: No CMVP-validated module for Arch — decide FIPS lane first | K27: In progress | N27: Phase 1. Same parent as V-270667 (GPOS V-203603). FIPS 140-3 key exchange on the SSH server. Same conclusion: not the public default. Owning the base repository is what would let a preset pin algorithms. Open finding when the check is written. | O27: Verify that the SSH daemon is configured to use only FIPS-validated key exchange algorithms with the following command: $ sudo grep -ir kexalgorithms /etc/ssh/sshd_config* KexAlgorithms ecdh-sha2-nistp521,ecdh-sha2-nistp384,ecdh-sha2-nistp256,diffie-hellman-group-exchange-sha256,diffie-hellman-group16-sha512,diffie-hellman-group14-sha256 If "KexAlgorithms" does not contain only the algorithms "ecdh-sha2-nistp521,ecdh-sha2-nistp384,ecdh-sha2-nistp256,diffie-hellman-group-exchange-sha256,diffie-hellman-group16-sha512,diffie-hellman-group14-sha256", is commented out, or is missing, this is a finding. | P27: Configure the SSH daemon to use only FIPS-validated key exchange algorithms by adding or modifying the following line in "/etc/ssh/sshd_config": KexAlgorithms ecdh-sha2-nistp521,ecdh-sha2-nistp384,ecdh-sha2-nistp256,diffie-hellman-group-exchange-sha256,diffie-hellman-group16-sha512,diffie-hellman-group14-sha256 Restart the "sshd" service for changes to take effect: $ sudo systemctl restart sshd | Q27: Without cryptographic integrity protections provided by FIPS-validated cryptographic algorithms, information can be viewed and altered by unauthorized users without detection. The system will attempt to use the first algorithm presented by the client that matches the server list.
A28: UBTU-24-100850 | B28: V-270670 | C28: CAT II | D28: SRG-OS-000250-GPOS-00093 | E28: CCI-001453 | F28: Ubuntu 24.04 LTS must configure the SSH client to use FIPS 140-3 approved ciphers to prevent the unauthorized disclosure of information and/or detect changes to information during transmission. | G28: Yes | H28: textfilecontent54 | I28: Build | J28: No CMVP-validated module for Arch — decide FIPS lane first | K28: In progress | N28: Phase 1. Same parent as V-270668 (GPOS V-203669). FIPS ciphers for the SSH client. Same conclusion as the sshd cipher rules. | O28: Verify the SSH client is configured to use only ciphers employing FIPS 140-3 approved algorithms with the following command: $ sudo grep -r 'Ciphers' /etc/ssh/ssh_config* Ciphers aes256-gcm@openssh.com,aes128-gcm@openssh.com,aes256-ctr,aes128-ctr If any ciphers other than "Ciphers aes256-gcm@openssh.com,aes128-gcm@openssh.com,aes256-ctr,aes128-ctr" are listed, the "Ciphers" keyword is missing, or the returned line is commented out, or if multiple conflicting ciphers are returned, this is a finding. | P28: Configure the Ubuntu 24.04 LTS SSH client to use only ciphers employing FIPS 140-3 approved algorithms by updating the "/etc/ssh/ssh_config" file with the following line: Ciphers aes256-gcm@openssh.com,aes128-gcm@openssh.com,aes256-ctr,aes128-ctr Restart the "ssh" service for changes to take effect: $ sudo systemctl restart ssh | Q28: Without cryptographic integrity protections, information can be altered by unauthorized users without detection. Remote access (e.g., RDP) is access to DOD nonpublic information systems by an authorized user (or an information system) communicating through an external, nonorganization-controlled network. Remote access methods include, for example, dial-up, broadband, and wireless. Nonlocal maintenance and diagnostic activities are those activities conducted by individuals communicating through a network, either an external network (e.g., the internet) or an internal network. Local maintenance and diagnostic activities are those activities carried out by individuals physically present at the information system or information system component and not communicating across a network connection. Encrypting information for transmission protects information from unauthorized disclosure and modification. Cryptographic mechanisms implemented to protect information integrity include, for example, cryptographic hash functions that have common application in digital signatures, checksums, and message authentication codes. By specifying a cipher list with the order of ciphers being in a "strongest to weakest" orientation, the system will automatically attempt to use the strongest cipher for securing SSH connections.
A29: UBTU-24-100860 | B29: V-270671 | C29: CAT II | D29: SRG-OS-000250-GPOS-00093 | E29: CCI-001453 | F29: Ubuntu 24.04 LTS SSH client must be configured to use only Message Authentication Codes (MACs) employing FIPS 140-3 validated cryptographic hash algorithms. | G29: Yes | H29: textfilecontent54 | I29: Build | J29: No CMVP-validated module for Arch — decide FIPS lane first | K29: In progress | N29: Phase 1. Same parent as V-270668 (GPOS V-203669). FIPS MACs for the SSH client. Same conclusion. | O29: Verify the SSH client is configured to only use MACs employing FIPS 140-3 approved algorithms with the following command: $ sudo grep -ir macs /etc/ssh/ssh_config* MACs hmac-sha2-512-etm@openssh.com,hmac-sha2-256-etm@openssh.com,hmac-sha2-512,hmac-sha2-256 If any MACs other than "hmac-sha2-512-etm@openssh.com,hmac-sha2-256-etm@openssh.com,hmac-sha2-512,hmac-sha2-256" are listed, or the returned line is commented out, this is a finding. | P29: Configure the Ubuntu 24.04 LTS SSH client to use only MACs employing FIPS 140-3 approved algorithms by updating the "/etc/ssh/ssh_config" file with the following line: MACs hmac-sha2-512-etm@openssh.com,hmac-sha2-256-etm@openssh.com,hmac-sha2-512,hmac-sha2-256 Restart the "ssh" service for changes to take effect: $ sudo systemctl restart ssh | Q29: Without cryptographic integrity protections, information can be altered by unauthorized users without detection. Remote access (e.g., RDP) is access to DOD nonpublic information systems by an authorized user (or an information system) communicating through an external, nonorganization-controlled network. Remote access methods include, for example, dial-up, broadband, and wireless. Nonlocal maintenance and diagnostic activities are those activities conducted by individuals communicating through a network, either an external network (e.g., the internet) or an internal network. Local maintenance and diagnostic activities are those activities carried out by individuals physically present at the information system or information system component and not communicating across a network connection. Encrypting information for transmission protects information from unauthorized disclosure and modification. Cryptographic mechanisms implemented to protect information integrity include, for example, cryptographic hash functions that have common application in digital signatures, checksums, and message authentication codes.
A30: UBTU-24-100900 | B30: V-270672 | C30: CAT II | D30: SRG-OS-000376-GPOS-00161 | E30: CCI-001953 | F30: Ubuntu 24.04 LTS must accept Personal Identity Verification (PIV) credentials. | G30: Yes | H30: dpkginfo | I30: Translate | J30: apt/dpkg → pacman -Q / pacman -Qkk / pacman.conf SigLevel | K30: Not started | O30: Verify the "opensc-pcks11" package is installed on the system with the following command: $ dpkg -l | grep opensc-pkcs11 ii opensc-pkcs11:amd64 0.25.0~rc1-1build2 amd64 Smart card utilities with support for PKCS#15 compatible cards If the "opensc-pcks11" package is not installed, this is a finding. | P30: Configure Ubuntu 24.04 LTS to accept PIV credentials. Install the "opensc-pkcs11" package using the following command: $ sudo apt install -y opensc-pkcs11 | Q30: The use of PIV credentials facilitates standardization and reduces the risk of unauthorized access. DOD has mandated the use of the common access card (CAC) to support identity management and personal authentication for systems covered under Homeland Security Presidential Directive (HSPD) 12, as well as making the CAC a primary component of layered protection for national security systems.
